I'm sorry, but an uncaught exception occurred.

While running game code:
  File "game/script.rpy", line 21, in script
    T "{sc = [2]}That’s me. Or, I guess, this is me{/sc}"
IndexError: tuple index out of range

-- Full Traceback ------------------------------------------------------------

Full traceback:
  File "game/script.rpy", line 21, in script
    T "{sc = [2]}That’s me. Or, I guess, this is me{/sc}"
  File "D:\renpy\renpy-8.0.3-sdk\renpy\ast.py", line 921, in execute
    renpy.exports.say(who, what, *args, **kwargs)
  File "D:\renpy\renpy-8.0.3-sdk\renpy\exports.py", line 1373, in say
    who(what, *args, **kwargs)
  File "D:\renpy\renpy-8.0.3-sdk\renpy\character.py", line 1253, in __call__
    what = self.prefix_suffix("what", self.what_prefix, what, self.what_suffix)
  File "D:\renpy\renpy-8.0.3-sdk\renpy\character.py", line 1172, in prefix_suffix
    return (sub(prefix) + sub(body) + sub(suffix))
  File "D:\renpy\renpy-8.0.3-sdk\renpy\character.py", line 1152, in sub
    return renpy.substitutions.substitute(s, scope=scope, force=force, translate=translate)[0]
  File "D:\renpy\renpy-8.0.3-sdk\renpy\substitutions.py", line 278, in substitute
    s = formatter.vformat(s, (), kwargs) # type: ignore
  File "/home/tom/ab/renpy-build/tmp/install.linux-x86_64/lib/python3.9/string.py", line 165, in vformat
  File "/home/tom/ab/renpy-build/tmp/install.linux-x86_64/lib/python3.9/string.py", line 205, in _vformat
  File "D:\renpy\renpy-8.0.3-sdk\renpy\substitutions.py", line 168, in get_field
    obj, arg_used = super(Formatter, self).get_field(field_name, args, kwargs)
  File "/home/tom/ab/renpy-build/tmp/install.linux-x86_64/lib/python3.9/string.py", line 270, in get_field
  File "/home/tom/ab/renpy-build/tmp/install.linux-x86_64/lib/python3.9/string.py", line 225, in get_value
IndexError: tuple index out of range

Windows-10-10.0.22621 AMD64
Ren'Py 8.0.3.22090809
Haustorial 1.0
Sat Feb  4 01:50:41 2023
